Workbook
Name NR_CARTOES: '99_AUX'!$G$2:$G$2
Name NR_CATEGORIAS: '99_AUX'!$D$2:$D$13
Name NR_CONTAS: '99_AUX'!$F$2:$F$5
Name NR_FORMAPGTO: '99_AUX'!$B$11:$B$15
Name NR_GRUPOS: '99_AUX'!$E$2:$E$5
Name NR_MESES: '99_AUX'!$B$18:$B$41
Name NR_SIMNAO: '99_AUX'!$B$2:$B$3
Name NR_STATUS: '99_AUX'!$B$8:$B$9
Name NR_SUBCATEGORIAS: '99_AUX'!$H$2:$H$17
Name NR_TIPO: '99_AUX'!$B$5:$B$6

Sheet 00_DASHBOARD
A1: FinanceOS V1 - Dashboard
A2: Mês de análise | B2: 2026-03
B4: Receitas do mês | E4: Despesas do mês | H4: Saldo do mês | K4: % orçamento usado
B5: ='99_AUX'!K3 -> 0 | E5: ='99_AUX'!K4 -> 0 | H5: ='99_AUX'!K5 -> 0 | K5: =IFERROR('99_AUX'!K4/SUMIFS('04_ORCAMENTO'!$C:$C,'04_ORCAMENTO'!$A:$A,B2),0) -> 0
A8: Despesas por categoria

Sheet 01_LANCAMENTOS
A1: ID | B1: Data | C1: Descrição | D1: Tipo (Receita/Despesa) | E1: Categoria | F1: Subcategoria | G1: Conta | H1: FormaPgto | I1: Cartão | J1: Valor | K1: Status (Pago/Pendente) | L1: Observações | M1: Tags | N1: MêsRef | O1: AnoRef
A2: =ROW()-1 -> 1 | B2: 46086 | C2: Salário mensal | D2: Receita | E2: Salário | G2: Nubank | H2: PIX | J2: 6500 | K2: Pago | M2: trabalho | N2: =TEXT(B2,"yyyy-mm") -> yyyy-03 | O2: =YEAR(B2) -> 2026
A3: =ROW()-1 -> 2 | B3: 46088 | C3: Mercado do mês | D3: Despesa | E3: Alimentação | F3: Mercado | G3: Inter | H3: Débito | J3: 850 | K3: Pago | L3: Compras casa | M3: casa | N3: =TEXT(B3,"yyyy-mm") -> yyyy-03 | O3: =YEAR(B3) -> 2026
A4: =ROW()-1 -> 3 | B4: 46089 | C4: Uber centro | D4: Despesa | E4: Transporte | F4: Uber/Taxi | G4: Nubank | H4: PIX | J4: 42.5 | K4: Pago | M4: mobilidade | N4: =TEXT(B4,"yyyy-mm") -> yyyy-03 | O4: =YEAR(B4) -> 2026
A5: =ROW()-1 -> 4 | B5: 46091 | C5: Notebook parcelado | D5: Despesa | E5: Compras | F5: Roupas | G5: Nubank | H5: Crédito | I5: Nubank | J5: 3200 | K5: Pendente | L5: 12x | M5: eletronico | N5: =TEXT(B5,"yyyy-mm") -> yyyy-03 | O5: =YEAR(B5) -> 2026
A6: =ROW()-1 -> 5 | B6: 46093 | C6: Aporte investimentos | D6: Despesa | E6: Investimentos | F6: Renda Fixa | G6: Investimentos | H6: PIX | J6: 1000 | K6: Pago | M6: invest | N6: =TEXT(B6,"yyyy-mm") -> yyyy-03 | O6: =YEAR(B6) -> 2026
A7: =ROW()-1 -> 6 | N7: =TEXT(B7,"yyyy-mm") -> yyyy-01 | O7: =YEAR(B7) -> 1900
A8: =ROW()-1 -> 7 | N8: =TEXT(B8,"yyyy-mm") -> yyyy-01 | O8: =YEAR(B8) -> 1900
A9: =ROW()-1 -> 8 | N9: =TEXT(B9,"yyyy-mm") -> yyyy-01 | O9: =YEAR(B9) -> 1900
A10: =ROW()-1 -> 9 | N10: =TEXT(B10,"yyyy-mm") -> yyyy-01 | O10: =YEAR(B10) -> 1900
A11: =ROW()-1 -> 10 | N11: =TEXT(B11,"yyyy-mm") -> yyyy-01 | O11: =YEAR(B11) -> 1900
A12: =ROW()-1 -> 11 | N12: =TEXT(B12,"yyyy-mm") -> yyyy-01 | O12: =YEAR(B12) -> 1900
A13: =ROW()-1 -> 12 | N13: =TEXT(B13,"yyyy-mm") -> yyyy-01 | O13: =YEAR(B13) -> 1900
A14: =ROW()-1 -> 13 | N14: =TEXT(B14,"yyyy-mm") -> yyyy-01 | O14: =YEAR(B14) -> 1900
A15: =ROW()-1 -> 14 | N15: =TEXT(B15,"yyyy-mm") -> yyyy-01 | O15: =YEAR(B15) -> 1900
A16: =ROW()-1 -> 15 | N16: =TEXT(B16,"yyyy-mm") -> yyyy-01 | O16: =YEAR(B16) -> 1900
A17: =ROW()-1 -> 16 | N17: =TEXT(B17,"yyyy-mm") -> yyyy-01 | O17: =YEAR(B17) -> 1900
A18: =ROW()-1 -> 17 | N18: =TEXT(B18,"yyyy-mm") -> yyyy-01 | O18: =YEAR(B18) -> 1900
... A2000: =ROW()-1 -> 1999 | N2000: =TEXT(B2000,"yyyy-mm") -> yyyy-01 | O2000: =YEAR(B2000) -> 1900

Sheet 02_CARTAO
A1: DataCompra | B1: Descrição | C1: Categoria | D1: Subcategoria | E1: Cartão | F1: ValorTotal | G1: Parcelas | H1: PrimeiraFatura (yyyy-mm) | I1: Observações | J1: GeradoEmLancamentos (Sim/Não)
A2: 46091 | B2: Notebook parcelado | C2: Compras | D2: Roupas | E2: Nubank | F2: 3200 | G2: 12 | H2: 2026-03 | I2: Compra de trabalho | J2: Não
A3: 46096 | B3: Curso online | C3: Educação | D3: Cursos | E3: Nubank | F3: 600 | G3: 6 | H3: 2026-03 | J3: Não

Sheet 03_METAS
A1: Meta | B1: ValorAlvo | C1: ValorAtual | D1: Progresso | E1: DataLimite | F1: Prioridade | G1: Status | H1: Observações
A2: Reserva de Emergência | B2: 20000 | C2: 4500 | D2: =IFERROR(C2/B2,0) -> 0.225 | E2: 46752 | F2: Alta | G2: Ativa | H2: Meta principal
A3: Entrada do Imóvel | B3: 80000 | C3: 12000 | D3: =IFERROR(C3/B3,0) -> 0.15 | E3: 46934 | F3: Média | G3: Ativa | H3: Longo prazo

Sheet 04_ORCAMENTO
A1: Mês (yyyy-mm) | B1: Categoria | C1: Orçado | D1: Realizado | E1: Diferença | F1: Alerta%
A2: 2026-03 | B2: Salário | C2: 7000 | D2: =SUMIFS('01_LANCAMENTOS'!$J:$J,'01_LANCAMENTOS'!$D:$D,"Despesa",'01_LANCAMENTOS'!$E:$E,B2,'01_LANCAMENTOS'!$N:$N,A2) -> 0 | E2: =C2-D2 -> 7000 | F2: 0.8
A3: 2026-03 | B3: Moradia | C3: 2500 | D3: =SUMIFS('01_LANCAMENTOS'!$J:$J,'01_LANCAMENTOS'!$D:$D,"Despesa",'01_LANCAMENTOS'!$E:$E,B3,'01_LANCAMENTOS'!$N:$N,A3) -> 0 | E3: =C3-D3 -> 2500 | F3: 0.8
A4: 2026-03 | B4: Alimentação | C4: 1200 | D4: =SUMIFS('01_LANCAMENTOS'!$J:$J,'01_LANCAMENTOS'!$D:$D,"Despesa",'01_LANCAMENTOS'!$E:$E,B4,'01_LANCAMENTOS'!$N:$N,A4) -> 0 | E4: =C4-D4 -> 1200 | F4: 0.8
A5: 2026-03 | B5: Transporte | C5: 500 | D5: =SUMIFS('01_LANCAMENTOS'!$J:$J,'01_LANCAMENTOS'!$D:$D,"Despesa",'01_LANCAMENTOS'!$E:$E,B5,'01_LANCAMENTOS'!$N:$N,A5) -> 0 | E5: =C5-D5 -> 500 | F5: 0.8
A6: 2026-03 | B6: Saúde | C6: 600 | D6: =SUMIFS('01_LANCAMENTOS'!$J:$J,'01_LANCAMENTOS'!$D:$D,"Despesa",'01_LANCAMENTOS'!$E:$E,B6,'01_LANCAMENTOS'!$N:$N,A6) -> 0 | E6: =C6-D6 -> 600 | F6: 0.8
A7: 2026-03 | B7: Lazer | C7: 400 | D7: =SUMIFS('01_LANCAMENTOS'!$J:$J,'01_LANCAMENTOS'!$D:$D,"Despesa",'01_LANCAMENTOS'!$E:$E,B7,'01_LANCAMENTOS'!$N:$N,A7) -> 0 | E7: =C7-D7 -> 400 | F7: 0.8
D8: =SUMIFS('01_LANCAMENTOS'!$J:$J,'01_LANCAMENTOS'!$D:$D,"Despesa",'01_LANCAMENTOS'!$E:$E,B8,'01_LANCAMENTOS'!$N:$N,A8) -> 0 | E8: =C8-D8 -> 0
D9: =SUMIFS('01_LANCAMENTOS'!$J:$J,'01_LANCAMENTOS'!$D:$D,"Despesa",'01_LANCAMENTOS'!$E:$E,B9,'01_LANCAMENTOS'!$N:$N,A9) -> 0 | E9: =C9-D9 -> 0
D10: =SUMIFS('01_LANCAMENTOS'!$J:$J,'01_LANCAMENTOS'!$D:$D,"Despesa",'01_LANCAMENTOS'!$E:$E,B10,'01_LANCAMENTOS'!$N:$N,A10) -> 0 | E10: =C10-D10 -> 0
D11: =SUMIFS('01_LANCAMENTOS'!$J:$J,'01_LANCAMENTOS'!$D:$D,"Despesa",'01_LANCAMENTOS'!$E:$E,B11,'01_LANCAMENTOS'!$N:$N,A11) -> 0 | E11: =C11-D11 -> 0
D12: =SUMIFS('01_LANCAMENTOS'!$J:$J,'01_LANCAMENTOS'!$D:$D,"Despesa",'01_LANCAMENTOS'!$E:$E,B12,'01_LANCAMENTOS'!$N:$N,A12) -> 0 | E12: =C12-D12 -> 0
D13: =SUMIFS('01_LANCAMENTOS'!$J:$J,'01_LANCAMENTOS'!$D:$D,"Despesa",'01_LANCAMENTOS'!$E:$E,B13,'01_LANCAMENTOS'!$N:$N,A13) -> 0 | E13: =C13-D13 -> 0
D14: =SUMIFS('01_LANCAMENTOS'!$J:$J,'01_LANCAMENTOS'!$D:$D,"Despesa",'01_LANCAMENTOS'!$E:$E,B14,'01_LANCAMENTOS'!$N:$N,A14) -> 0 | E14: =C14-D14 -> 0
D15: =SUMIFS('01_LANCAMENTOS'!$J:$J,'01_LANCAMENTOS'!$D:$D,"Despesa",'01_LANCAMENTOS'!$E:$E,B15,'01_LANCAMENTOS'!$N:$N,A15) -> 0 | E15: =C15-D15 -> 0
D16: =SUMIFS('01_LANCAMENTOS'!$J:$J,'01_LANCAMENTOS'!$D:$D,"Despesa",'01_LANCAMENTOS'!$E:$E,B16,'01_LANCAMENTOS'!$N:$N,A16) -> 0 | E16: =C16-D16 -> 0
D17: =SUMIFS('01_LANCAMENTOS'!$J:$J,'01_LANCAMENTOS'!$D:$D,"Despesa",'01_LANCAMENTOS'!$E:$E,B17,'01_LANCAMENTOS'!$N:$N,A17) -> 0 | E17: =C17-D17 -> 0
D18: =SUMIFS('01_LANCAMENTOS'!$J:$J,'01_LANCAMENTOS'!$D:$D,"Despesa",'01_LANCAMENTOS'!$E:$E,B18,'01_LANCAMENTOS'!$N:$N,A18) -> 0 | E18: =C18-D18 -> 0
D19: =SUMIFS('01_LANCAMENTOS'!$J:$J,'01_LANCAMENTOS'!$D:$D,"Despesa",'01_LANCAMENTOS'!$E:$E,B19,'01_LANCAMENTOS'!$N:$N,A19) -> 0 | E19: =C19-D19 -> 0
... D2000: =SUMIFS('01_LANCAMENTOS'!$J:$J,'01_LANCAMENTOS'!$D:$D,"Despesa",'01_LANCAMENTOS'!$E:$E,B2000,'01_LANCAMENTOS'!$N:$N,A2000) -> 0 | E2000: =C2000-D2000 -> 0

Sheet 90_CATEGORIAS
A1: Categoria | B1: Subcategoria | C1: Grupo | D1: Ativo (Sim/Não)
A2: Salário | C2: Receitas | D2: Sim
A3: Renda Extra | C3: Receitas | D3: Sim
A4: Moradia | B4: Aluguel | C4: Essenciais | D4: Sim
A5: Moradia | B5: Condomínio | C5: Essenciais | D5: Sim
A6: Alimentação | B6: Mercado | C6: Essenciais | D6: Sim
A7: Alimentação | B7: Restaurante | C7: Essenciais | D7: Sim
A8: Transporte | B8: Uber/Taxi | C8: Essenciais | D8: Sim
A9: Transporte | B9: Combustível | C9: Essenciais | D9: Sim
A10: Saúde | B10: Farmácia | C10: Essenciais | D10: Sim
A11: Saúde | B11: Plano de Saúde | C11: Essenciais | D11: Sim
A12: Investimentos | B12: Renda Fixa | C12: Dívidas/Poupar | D12: Sim
A13: Investimentos | B13: Ações/Fundos | C13: Dívidas/Poupar | D13: Sim
A14: Dívidas | B14: Empréstimos | C14: Dívidas/Poupar | D14: Sim
A15: Dívidas | B15: Cartão (juros) | C15: Dívidas/Poupar | D15: Sim
... A19: Outros | B19: Diversos | C19: Outros | D19: Sim

Sheet 91_CONTAS
A1: Conta | B1: TipoConta | C1: SaldoInicial | D1: Ativo (Sim/Não)
A2: Nubank | B2: Corrente | C2: 0 | D2: Sim
A3: Inter | B3: Corrente | C3: 0 | D3: Sim
A4: Dinheiro | B4: Dinheiro | C4: 0 | D4: Sim
A5: Investimentos | B5: Investimentos | C5: 0 | D5: Sim

Sheet 92_CARTOES
A1: Cartão | B1: FechamentoDia (1-31) | C1: VencimentoDia (1-31) | D1: Limite | E1: Ativo (Sim/Não)
A2: Nubank | B2: 20 | C2: 25 | D2: 8000 | E2: Sim

Sheet 93_REGRAS
A1: ContémTexto | B1: Categoria | C1: Subcategoria | D1: Tipo (Receita/Despesa) | E1: Prioridade | F1: Ativo (Sim/Não)
A2: UBER | B2: Transporte | C2: Uber/Taxi | D2: Despesa | E2: 1 | F2: Sim
A3: MERCADO | B3: Alimentação | C3: Mercado | D3: Despesa | E3: 2 | F3: Sim
A4: SALARIO | B4: Salário | D4: Receita | E4: 1 | F4: Sim

Sheet 99_AUX
A1: Lista | B1: Valor | D1: CategoriasAtivas | E1: Grupos | F1: ContasAtivas | G1: CartoesAtivos | H1: Subcategorias | J1: Tabelas para Dashboard
A2: NR_SIMNAO | B2: Sim | D2: Salário | E2: Receitas | F2: Nubank | G2: Nubank | H2: Aluguel | J2: Mês selecionado | K2: ='00_DASHBOARD'!B2 -> 2026-03
B3: Não | D3: Renda Extra | E3: Essenciais | F3: Inter | H3: Condomínio | J3: TotalReceitasMes | K3: =SUMIFS('01_LANCAMENTOS'!$J:$J,'01_LANCAMENTOS'!$D:$D,"Receita",'01_LANCAMENTOS'!$N:$N,K2) -> 0
D4: Moradia | E4: Dívidas/Poupar | F4: Dinheiro | H4: Mercado | J4: TotalDespesasMes | K4: =SUMIFS('01_LANCAMENTOS'!$J:$J,'01_LANCAMENTOS'!$D:$D,"Despesa",'01_LANCAMENTOS'!$N:$N,K2) -> 0
A5: NR_TIPO | B5: Receita | D5: Alimentação | E5: Outros | F5: Investimentos | H5: Restaurante | J5: SaldoMes | K5: =K3-K4 -> 0
B6: Despesa | D6: Transporte | H6: Uber/Taxi
D7: Saúde | H7: Combustível | J7: Categoria | K7: Valor
A8: NR_STATUS | B8: Pago | D8: Investimentos | H8: Farmácia | J8: Salário | K8: =SUMIFS('01_LANCAMENTOS'!$J:$J,'01_LANCAMENTOS'!$D:$D,"Despesa",'01_LANCAMENTOS'!$E:$E,J8,'01_LANCAMENTOS'!$N:$N,K2) -> 0
B9: Pendente | D9: Dívidas | H9: Plano de Saúde | J9: Renda Extra | K9: =SUMIFS('01_LANCAMENTOS'!$J:$J,'01_LANCAMENTOS'!$D:$D,"Despesa",'01_LANCAMENTOS'!$E:$E,J9,'01_LANCAMENTOS'!$N:$N,K2) -> 0
D10: Lazer | H10: Renda Fixa | J10: Moradia | K10: =SUMIFS('01_LANCAMENTOS'!$J:$J,'01_LANCAMENTOS'!$D:$D,"Despesa",'01_LANCAMENTOS'!$E:$E,J10,'01_LANCAMENTOS'!$N:$N,K2) -> 0
A11: NR_FORMAPGTO | B11: PIX | D11: Compras | H11: Ações/Fundos | J11: Alimentação | K11: =SUMIFS('01_LANCAMENTOS'!$J:$J,'01_LANCAMENTOS'!$D:$D,"Despesa",'01_LANCAMENTOS'!$E:$E,J11,'01_LANCAMENTOS'!$N:$N,K2) -> 0
B12: Débito | D12: Educação | H12: Empréstimos | J12: Transporte | K12: =SUMIFS('01_LANCAMENTOS'!$J:$J,'01_LANCAMENTOS'!$D:$D,"Despesa",'01_LANCAMENTOS'!$E:$E,J12,'01_LANCAMENTOS'!$N:$N,K2) -> 0
B13: Crédito | D13: Outros | H13: Cartão (juros) | J13: Saúde | K13: =SUMIFS('01_LANCAMENTOS'!$J:$J,'01_LANCAMENTOS'!$D:$D,"Despesa",'01_LANCAMENTOS'!$E:$E,J13,'01_LANCAMENTOS'!$N:$N,K2) -> 0
B14: Dinheiro | H14: Cinema/Shows | J14: Investimentos | K14: =SUMIFS('01_LANCAMENTOS'!$J:$J,'01_LANCAMENTOS'!$D:$D,"Despesa",'01_LANCAMENTOS'!$E:$E,J14,'01_LANCAMENTOS'!$N:$N,K2) -> 0
B15: Boleto | H15: Roupas | J15: Dívidas | K15: =SUMIFS('01_LANCAMENTOS'!$J:$J,'01_LANCAMENTOS'!$D:$D,"Despesa",'01_LANCAMENTOS'!$E:$E,J15,'01_LANCAMENTOS'!$N:$N,K2) -> 0
H16: Cursos | J16: Lazer | K16: =SUMIFS('01_LANCAMENTOS'!$J:$J,'01_LANCAMENTOS'!$D:$D,"Despesa",'01_LANCAMENTOS'!$E:$E,J16,'01_LANCAMENTOS'!$N:$N,K2) -> 0
H17: Diversos | J17: Compras | K17: =SUMIFS('01_LANCAMENTOS'!$J:$J,'01_LANCAMENTOS'!$D:$D,"Despesa",'01_LANCAMENTOS'!$E:$E,J17,'01_LANCAMENTOS'!$N:$N,K2) -> 0
A18: NR_MESES | B18: 2026-01 | J18: Educação | K18: =SUMIFS('01_LANCAMENTOS'!$J:$J,'01_LANCAMENTOS'!$D:$D,"Despesa",'01_LANCAMENTOS'!$E:$E,J18,'01_LANCAMENTOS'!$N:$N,K2) -> 0
B19: 2026-02 | J19: Outros | K19: =SUMIFS('01_LANCAMENTOS'!$J:$J,'01_LANCAMENTOS'!$D:$D,"Despesa",'01_LANCAMENTOS'!$E:$E,J19,'01_LANCAMENTOS'!$N:$N,K2) -> 0
B20: 2026-03
B21: 2026-04
B22: 2026-05
B23: 2026-06
B24: 2026-07
B25: 2026-08
B26: 2026-09
B27: 2026-10
B28: 2026-11
B29: 2026-12
B30: 2027-01 | J30: Instruções
B31: 2027-02 | J31: No Google Sheets, Apps Script gera parcelas em 01_LANCAMENTOS.
B32: 2027-03
B33: 2027-04 | J33: Exemplo divisão
B34: 2027-05 | J34: ValorTotal | K34: 1200
B35: 2027-06 | J35: Parcelas | K35: 6
B36: 2027-07 | J36: ValorParcela | K36: =IFERROR(K34/K35,0) -> 200
B37: 2027-08
B38: 2027-09
B39: 2027-10
B40: 2027-11
...
